Traceback (most recent call last):

  File "d:\projects\Data_Science_and_Co_TU_Wien\BA\scripts\trainUrbanCV.py", line 460, in <module>
    cv_results = run_cross_validation()

  File "d:\projects\Data_Science_and_Co_TU_Wien\BA\scripts\trainUrbanCV.py", line 421, in run_cross_validation
    fold_results = train_fold(
        fold=fold,
    ...<10 lines>...
        use_validation=use_validation
    )

  File "d:\projects\Data_Science_and_Co_TU_Wien\BA\scripts\trainUrbanCV.py", line 328, in train_fold
    train_loss, train_acc, sub_epoch_info = train_one_epoch(
                                            ~~~~~~~~~~~~~~~^
        model, criterion, optimizer, train_loader,
        ^^^^^^^^^^^^^^^^^^^^^^^^^^^^^^^^^^^^^^^^^^
        regularize=True, scheduler=scheduler,
        ^^^^^^^^^^^^^^^^^^^^^^^^^^^^^^^^^^^^^
        sub_epoch_documentation=10, augments_use=augments
        ^^^^^^^^^^^^^^^^^^^^^^^^^^^^^^^^^^^^^^^^^^^^^^^^^
    )
    ^

  File "d:\projects\Data_Science_and_Co_TU_Wien\BA\efficientSsmLukin\utils.py", line 92, in train_one_epoch
    last_loss = alpha*loss_weight.item() + (1-alpha)*last_loss
                      ~~~~~~~~~~~~~~~~^^

RuntimeError: CUDA error: unknown error
CUDA kernel errors might be asynchronously reported at some other API call, so the stacktrace below might be incorrect.
For debugging consider passing CUDA_LAUNCH_BLOCKING=1
Compile with `TORCH_USE_CUDA_DSA` to enable device-side assertions.


